`Upload.py`でリポジトリ生成後、続けて削除すると以下のエラー発生。

```sh
...
Response.end---------------------
削除しました。
Exception during reset or similar
Traceback (most recent call last):
  File "/home/pi/root/env/py/auto_github/lib/python3.6/site-packages/sqlalchemy/pool.py", line 703, in _finalize_fairy
    fairy._reset(pool)
  File "/home/pi/root/env/py/auto_github/lib/python3.6/site-packages/sqlalchemy/pool.py", line 873, in _reset
    pool._dialect.do_rollback(self)
  File "/home/pi/root/env/py/auto_github/lib/python3.6/site-packages/sqlalchemy/engine/default.py", line 457, in do_rollback
    dbapi_connection.rollback()
sqlite3.ProgrammingError: SQLite objects created in a thread can only be used in that same thread.The object was created in thread id 1972261984 and this is thread id 1995563008
Exception closing connection <sqlite3.Connection object at 0x7590bda0>
Traceback (most recent call last):
  File "/home/pi/root/env/py/auto_github/lib/python3.6/site-packages/sqlalchemy/pool.py", line 703, in _finalize_fairy
    fairy._reset(pool)
  File "/home/pi/root/env/py/auto_github/lib/python3.6/site-packages/sqlalchemy/pool.py", line 873, in _reset
    pool._dialect.do_rollback(self)
  File "/home/pi/root/env/py/auto_github/lib/python3.6/site-packages/sqlalchemy/engine/default.py", line 457, in do_rollback
    dbapi_connection.rollback()
sqlite3.ProgrammingError: SQLite objects created in a thread can only be used in that same thread.The object was created in thread id 1972261984 and this is thread id 1995563008

During handling of the above exception, another exception occurred:

Traceback (most recent call last):
  File "/home/pi/root/env/py/auto_github/lib/python3.6/site-packages/sqlalchemy/pool.py", line 317, in _close_connection
    self._dialect.do_close(connection)
  File "/home/pi/root/env/py/auto_github/lib/python3.6/site-packages/sqlalchemy/engine/default.py", line 463, in do_close
    dbapi_connection.close()
sqlite3.ProgrammingError: SQLite objects created in a thread can only be used in that same thread.The object was created in thread id 1972261984 and this is thread id 1995563008
```

`sqlite3.ProgrammingError`エラーはマルチスレッドで発生する。 [参考](https://tonton7.blogspot.jp/2011/05/python-sqlite.html)

```sh
sqlite3.ProgrammingError: SQLite objects created in a thread can only be used in that same thread.The object was created in thread id 1972261984 and this is thread id 1995563008
```

SQLite3はそういうもの。

* 発生したタイミング（確認した限り）
    * `Upload.py`
        * アップロードして終了後（「終了します。」メッセージ直後）
        * アップロードして続けざまに削除後（「削除しました。」メッセージ直後）

このタイミング後にマルチスレッドでDB操作なんてしてないはず。

また、エラーメッセージから自分が書いたコードの箇所が表示されない。一体どこでエラーになったのか謎。


https://stackoverflow.com/questions/393554/python-sqlite3-and-concurrency
http://dataset.readthedocs.io/en/latest/api.html?highlight=connect
http://docs.sqlalchemy.org/en/latest/dialects/sqlite.html

と思ったら、しばらくして再度実行するとエラーが消えた。謎。

